<!DOCTYPE html><html lang="zh-CN"><head><meta charset="utf-8"><meta name="X-UA-Compatible" content="IE=edge"><meta name="author" content="张宇辰 (pw)"><title>Node 出现 uncaughtException 之后的优雅退出方案 · 张宇辰的博客</title><meta name="description" content="Node 的异步特性是它最大的魅力，但是在带来便利的同时也带来了不少麻烦和坑，错误捕获就是一个。由于 Node 的异步特性，导致我们无法使用 try/catch 来捕获回调函数中的异常，例如:
123456789101112try &amp;#123;    console.log('进入 try/catc"><meta name="keywords"><meta content="width=device-width, initial-scale=1.0, maximum-scale=1.0, user-scalable=0" name="viewport"><meta content="yes" name="apple-mobile-web-app-capable"><meta content="black" name="apple-mobile-web-app-status-bar-style"><meta content="telephone=no" name="format-detection"><meta name="renderer" content="webkit"><link rel="short icon" href="/images/favicon.png" type="image/x-icon"><link rel="stylesheet" href="/css/style.css"><link rel="stylesheet" href="/css/blog_basic.css"><link rel="stylesheet" href="/css/font-awesome.min.css"><link rel="alternate" type="application/atom+xml" title="ATOM 1.0" href="/atom.xml"><meta name="generator" content="Hexo 4.2.0"></head><body><div class="sidebar animated fadeInDown"><div class="image-info">2019 年夏 @ 内蒙响沙湾</div></div><div class="main"><div class="page-top animated fadeInDown"><div class="nav"><li><a href="/">首页</a></li><li><a href="/archives">归档</a></li></div><div class="information"><div class="back_btn"><li><a class="fa fa-chevron-left" onclick="window.history.go(-1)"> </a></li></div></div></div><div class="autopagerize_page_element"><div class="content"><div class="post-page"><div class="post animated fadeInDown"><div class="post-title"><h1><a href="/2014/01/25/handle-exception-in-node/">Node 出现 uncaughtException 之后的优雅退出方案</a></h1></div><div class="post-content"><p>Node 的异步特性是它最大的魅力，但是在带来便利的同时也带来了不少麻烦和坑，错误捕获就是一个。由于 Node 的异步特性，导致我们无法使用 try/catch 来捕获回调函数中的异常，例如:</p>
<figure class="highlight javascript"><table><tr><td class="gutter"><pre><span class="line">1</span><br><span class="line">2</span><br><span class="line">3</span><br><span class="line">4</span><br><span class="line">5</span><br><span class="line">6</span><br><span class="line">7</span><br><span class="line">8</span><br><span class="line">9</span><br><span class="line">10</span><br><span class="line">11</span><br><span class="line">12</span><br></pre></td><td class="code"><pre><span class="line"><span class="keyword">try</span> &#123;</span><br><span class="line">    <span class="built_in">console</span>.log(<span class="string">'进入 try/catch'</span>);</span><br><span class="line">    <span class="built_in">require</span>(<span class="string">'fs'</span>).stat(<span class="string">'SOME_FILE_DOES_NOT_EXIST'</span>, <span class="function"><span class="keyword">function</span> <span class="title">readCallback</span>(<span class="params">err, content</span>) </span>&#123;</span><br><span class="line">        <span class="keyword">if</span> (err) &#123;</span><br><span class="line">            <span class="keyword">throw</span> err; <span class="comment">// 抛出异常</span></span><br><span class="line">        &#125;</span><br><span class="line">    &#125;);</span><br><span class="line">&#125; <span class="keyword">catch</span> (e) &#123;</span><br><span class="line">    <span class="comment">// 这里捕获不到 readCallback 函数中抛出的异常</span></span><br><span class="line">&#125; <span class="keyword">finally</span> &#123;</span><br><span class="line">    <span class="built_in">console</span>.log(<span class="string">'离开 try/catch'</span>);</span><br><span class="line">&#125;</span><br></pre></td></tr></table></figure>

<p>运行结果是:</p>
<figure class="highlight plain"><table><tr><td class="gutter"><pre><span class="line">1</span><br><span class="line">2</span><br><span class="line">3</span><br><span class="line">4</span><br><span class="line">5</span><br><span class="line">6</span><br><span class="line">7</span><br></pre></td><td class="code"><pre><span class="line">进入 try&#x2F;catch</span><br><span class="line">离开 try&#x2F;catch</span><br><span class="line"></span><br><span class="line">test.js:7</span><br><span class="line">            throw err; &#x2F;&#x2F; 抛出异常</span><br><span class="line">                  ^</span><br><span class="line">Error: ENOENT, stat &#39;SOME_FILE_DOES_NOT_EXIST&#39;</span><br></pre></td></tr></table></figure>

<p>上面代码中由于 <code>fs.stat</code> 去查询一个不存在的文件的状态，导致 <code>readCallback</code> 抛出了一个异常。由于 <code>fs.read</code> 的异步特性，<code>readCallback</code> 函数的调用发生在 <code>try/catch</code> 块结束之后，所以该异常不会被 try/catch 捕获。之后 Node 会触发 <code>uncaughtException</code> 事件，如果这个事件依然没有得到响应，整个进程(<code>process</code>)就会 crash。</p>
<p>程序员永远无法保证代码中不出现 <code>uncaughtException</code>，即便是自己代码写的足够小心，也不能保证用的第三方模块没有 bug，例如:</p>
<figure class="highlight javascript"><table><tr><td class="gutter"><pre><span class="line">1</span><br><span class="line">2</span><br><span class="line">3</span><br><span class="line">4</span><br><span class="line">5</span><br><span class="line">6</span><br><span class="line">7</span><br><span class="line">8</span><br><span class="line">9</span><br></pre></td><td class="code"><pre><span class="line"><span class="keyword">var</span> deserialize = <span class="built_in">require</span>(<span class="string">'deserialize'</span>); <span class="comment">// 假设 deserialize 是一个带有 bug 的第三方模块</span></span><br><span class="line"></span><br><span class="line"><span class="comment">// app 是一个 express 服务对象</span></span><br><span class="line">app.get(<span class="string">'/users'</span>, <span class="function"><span class="keyword">function</span> (<span class="params">req, res</span>) </span>&#123;</span><br><span class="line">    mysql.query(<span class="string">'SELECT * FROM user WHERE id=1'</span>, <span class="function"><span class="keyword">function</span> (<span class="params">err, user</span>) </span>&#123;</span><br><span class="line">        <span class="keyword">var</span> config = deserialize(user.config); <span class="comment">// 假如这里触发了 deserialize 的 bug</span></span><br><span class="line">        res.send(config);</span><br><span class="line">    &#125;);</span><br><span class="line">&#125;);</span><br></pre></td></tr></table></figure>

<p>如果不幸触发了 <code>deserialize</code> 模块的 bug，这里就会抛出一个异常，最终结果是整个服务 crash。</p>
<p>当这种情况发生在 Web 服务上时结果是灾难性的。<code>uncaughtException</code> 错误会导致当前的所有的用户连接都被中断，甚至不能返回一个正常的 HTTP 错误码，用户只能等到浏览器超时才能看到一个 <code>no data received</code> 错误。</p>
<p>这是一种非常野蛮粗暴的异常处理机制，任何线上服务都不应该因为 <code>uncaughtException</code> 导致服务器崩溃。一个友好的错误处理机制应该满足三个条件:</p>
<ol>
<li>对于引发异常的用户，返回 500 页面</li>
<li>其他用户不受影响，可以正常访问</li>
<li>不影响整个进程的正常运行</li>
</ol>
<p>很遗憾的是，保证 <code>uncaughtException</code> 不影响整个进程的健康运转是不可能的。当 Node 抛出 <code>uncaughtException</code> 异常时就会丢失当前环境的堆栈，导致 Node 不能正常进行内存回收。也就是说，每一次 <code>uncaughtException</code> 都有可能导致内存泄露。</p>
<p>既然如此，退而求其次，我们可以在满足前两个条件的情况下退出进程以便重启服务。</p>
<h2 id="用-domain-来捕获异步异常"><a href="#用-domain-来捕获异步异常" class="headerlink" title="用 domain 来捕获异步异常"></a>用 domain 来捕获异步异常</h2><p>普遍的思路是，如果可以通过某种方式来捕获回调函数中的异常，那么就不会有 <code>uncaughtException</code> 错误导致的崩溃。为了解决这个问题，Node 0.8 之后的版本新增了 <code>domain</code> 模块，它可以用来捕获回调函数中抛出的异常。</p>
<p><code>domain</code> 主要的 API 有 <code>domain.run</code> 和 <code>error</code> 事件。简单的说，通过 <code>domain.run</code> 执行的函数中引发的异常都可以通过 <code>domain</code> 的 <code>error</code> 事件捕获，例如:</p>
<figure class="highlight javascript"><table><tr><td class="gutter"><pre><span class="line">1</span><br><span class="line">2</span><br><span class="line">3</span><br><span class="line">4</span><br><span class="line">5</span><br><span class="line">6</span><br><span class="line">7</span><br><span class="line">8</span><br><span class="line">9</span><br><span class="line">10</span><br><span class="line">11</span><br></pre></td><td class="code"><pre><span class="line"><span class="keyword">var</span> domain = <span class="built_in">require</span>(<span class="string">'domain'</span>);</span><br><span class="line"><span class="keyword">var</span> d = domain.create();</span><br><span class="line">d.run(<span class="function"><span class="keyword">function</span> (<span class="params"></span>) </span>&#123;</span><br><span class="line">    setTimeout(<span class="function"><span class="keyword">function</span> (<span class="params"></span>) </span>&#123;</span><br><span class="line">        <span class="keyword">throw</span> <span class="keyword">new</span> <span class="built_in">Error</span>(<span class="string">'async error'</span>); <span class="comment">// 抛出一个异步异常</span></span><br><span class="line">    &#125;, <span class="number">1000</span>);</span><br><span class="line">&#125;);</span><br><span class="line"></span><br><span class="line">d.on(<span class="string">'error'</span>, <span class="function"><span class="keyword">function</span> (<span class="params">err</span>) </span>&#123;</span><br><span class="line">    <span class="built_in">console</span>.log(<span class="string">'catch err:'</span>, err); <span class="comment">// 这里可以捕获异步异常</span></span><br><span class="line">&#125;);</span><br></pre></td></tr></table></figure>

<p>通过 <code>domain</code> 模块，以及 JavaScript 的词法作用域特性，可以很轻易的为引发异常的用户返回 500 页面。以 express 为例:</p>
<figure class="highlight javascript"><table><tr><td class="gutter"><pre><span class="line">1</span><br><span class="line">2</span><br><span class="line">3</span><br><span class="line">4</span><br><span class="line">5</span><br><span class="line">6</span><br><span class="line">7</span><br><span class="line">8</span><br><span class="line">9</span><br><span class="line">10</span><br><span class="line">11</span><br><span class="line">12</span><br><span class="line">13</span><br><span class="line">14</span><br><span class="line">15</span><br><span class="line">16</span><br><span class="line">17</span><br><span class="line">18</span><br></pre></td><td class="code"><pre><span class="line"><span class="keyword">var</span> app = express();</span><br><span class="line"><span class="keyword">var</span> server = <span class="built_in">require</span>(<span class="string">'http'</span>).createServer(app);</span><br><span class="line"><span class="keyword">var</span> domain = <span class="built_in">require</span>(<span class="string">'domain'</span>);</span><br><span class="line"></span><br><span class="line">app.use(<span class="function"><span class="keyword">function</span> (<span class="params">req, res, next</span>) </span>&#123;</span><br><span class="line">    <span class="keyword">var</span> reqDomain = domain.create();</span><br><span class="line">    reqDomain.on(<span class="string">'error'</span>, <span class="function"><span class="keyword">function</span> (<span class="params">err</span>) </span>&#123; <span class="comment">// 下面抛出的异常在这里被捕获</span></span><br><span class="line">        res.send(<span class="number">500</span>, err.stack); <span class="comment">// 成功给用户返回了 500</span></span><br><span class="line">    &#125;);</span><br><span class="line"></span><br><span class="line">    reqDomain.run(next);</span><br><span class="line">&#125;);</span><br><span class="line"></span><br><span class="line">app.get(<span class="string">'/'</span>, <span class="function"><span class="keyword">function</span> (<span class="params"></span>) </span>&#123;</span><br><span class="line">    setTimeout(<span class="function"><span class="keyword">function</span> (<span class="params"></span>) </span>&#123;</span><br><span class="line">        <span class="keyword">throw</span> <span class="keyword">new</span> <span class="built_in">Error</span>(<span class="string">'async exception'</span>); <span class="comment">// 抛出一个异步异常</span></span><br><span class="line">    &#125;, <span class="number">1000</span>);</span><br><span class="line">&#125;);</span><br></pre></td></tr></table></figure>

<p>上面的代码将 domain 作为一个中间件来使用，保证之后 express 所有的中间件都在 <code>domain.run</code> 函数内部执行。这些中间件内的异常都可以通过 <code>error</code> 事件来捕获。</p>
<p>尽管借助于闭包，我们可以正常的给用户返回 500 错误，但是 <code>domain</code> 捕获到错误时依然会丢失堆栈信息，此时已经无法保证程序的健康运行，必须退出。Node http server 提供了 <code>close</code> 方法，该方法在调用时会停止 server 接收新的请求，但不会断开当前已经建立的连接。</p>
<figure class="highlight javascript"><table><tr><td class="gutter"><pre><span class="line">1</span><br><span class="line">2</span><br><span class="line">3</span><br><span class="line">4</span><br><span class="line">5</span><br><span class="line">6</span><br><span class="line">7</span><br><span class="line">8</span><br><span class="line">9</span><br><span class="line">10</span><br><span class="line">11</span><br><span class="line">12</span><br><span class="line">13</span><br><span class="line">14</span><br><span class="line">15</span><br><span class="line">16</span><br></pre></td><td class="code"><pre><span class="line">reqDomain.on(<span class="string">'error'</span>, <span class="function"><span class="keyword">function</span> (<span class="params"></span>) </span>&#123;</span><br><span class="line">    <span class="keyword">try</span> &#123;</span><br><span class="line">        <span class="comment">// 强制退出机制</span></span><br><span class="line">        <span class="keyword">var</span> killTimer = setTimeout(<span class="function"><span class="keyword">function</span> (<span class="params"></span>) </span>&#123;</span><br><span class="line">            process.exit(<span class="number">1</span>);</span><br><span class="line">        &#125;, <span class="number">30000</span>);</span><br><span class="line">        killTimer.unref(); <span class="comment">// 非常重要</span></span><br><span class="line"></span><br><span class="line">        <span class="comment">// 自动退出机制，停止接收新链接，等待当前已建立连接的关闭</span></span><br><span class="line">        server.close(<span class="function"><span class="keyword">function</span> (<span class="params"></span>) </span>&#123;</span><br><span class="line">            <span class="comment">// 此时所有连接均已关闭，此时 Node 会自动退出，不需要再调用 process.exit(1) 来结束进程</span></span><br><span class="line">        &#125;);</span><br><span class="line">    &#125; <span class="keyword">catch</span>(e) &#123;</span><br><span class="line">        <span class="built_in">console</span>.log(<span class="string">'err'</span>, e.stack);</span><br><span class="line">    &#125;</span><br><span class="line">&#125;);</span><br></pre></td></tr></table></figure>

<p>这个例子来自 Node 的文档。其中有几个关键点：</p>
<ul>
<li>Node 有个非常好的特性，所有连接都被释放后进程会自动结束，所以不需要再 <code>server.close</code> 方法的回调函数中退出进程</li>
<li>强制退出机制: 因为用户连接有可能因为某些原因无法释放，在这种情况下应该强制退出整个进程。</li>
<li><code>killTimer.unref()</code>: 如果不使用 <code>unref</code> 方法，那么即使 server 的所有连接都关闭，Node 也会保持运行直到 <code>killTimer</code> 的回调函数被调用。<code>unref</code> 可以创建一个”不保持程序运行”的计时器。</li>
<li>处理异常时要小心的把异常处理逻辑用 try/catch 包住，避免处理异常时抛出新的异常</li>
</ul>
<p>通过 <code>domain</code> 似乎就已经解决了我们的需求: 给触发异常的用户一个 500，停止接收新请求，提供正常的服务给已经建立连接的用户，直到所有请求都已结束，退出进程。但是，理想很丰满，现实很骨感，<code>domain</code> 有个最大的问题，它<a href="http://cnodejs.org/topic/516b64596d38277306407936" target="_blank" rel="noopener">不能捕获所有的异步异常</a>！。也就是说，即使用了 <code>domain</code>，程序依然有因为 <code>uncaughtException</code> crash 的可能。</p>
<p>所幸的是我们可以监听 <code>uncaughtException</code> 事件。</p>
<h2 id="uncaughtException-事件"><a href="#uncaughtException-事件" class="headerlink" title="uncaughtException 事件"></a><code>uncaughtException</code> 事件</h2><p><code>uncaughtException</code> 是一个非常古老的事件。当 Node 发现一个未捕获的异常时，会触发这个事件。并且如果这个事件存在回调函数，Node 就不会强制结束进程。这个特性，可以用来弥补 <code>domain</code> 的不足:</p>
<figure class="highlight javascript"><table><tr><td class="gutter"><pre><span class="line">1</span><br><span class="line">2</span><br><span class="line">3</span><br><span class="line">4</span><br><span class="line">5</span><br><span class="line">6</span><br><span class="line">7</span><br><span class="line">8</span><br><span class="line">9</span><br><span class="line">10</span><br><span class="line">11</span><br><span class="line">12</span><br><span class="line">13</span><br><span class="line">14</span><br></pre></td><td class="code"><pre><span class="line">process.on(<span class="string">'uncaughtException'</span>, <span class="function"><span class="keyword">function</span> (<span class="params">err</span>) </span>&#123;</span><br><span class="line">    <span class="built_in">console</span>.log(err);</span><br><span class="line"></span><br><span class="line">    <span class="keyword">try</span> &#123;</span><br><span class="line">        <span class="keyword">var</span> killTimer = setTimeout(<span class="function"><span class="keyword">function</span> (<span class="params"></span>) </span>&#123;</span><br><span class="line">            process.exit(<span class="number">1</span>);</span><br><span class="line">        &#125;, <span class="number">30000</span>);</span><br><span class="line">        killTimer.unref();</span><br><span class="line"></span><br><span class="line">        server.close();</span><br><span class="line">    &#125; <span class="keyword">catch</span> (e) &#123;</span><br><span class="line">        <span class="built_in">console</span>.log(<span class="string">'error when exit'</span>, e.stack);</span><br><span class="line">    &#125;</span><br><span class="line">&#125;);</span><br></pre></td></tr></table></figure>

<p><code>uncaughtException</code> 事件的缺点在于无法为抛出异常的用户请求返回一个 500 错误，这是由于 <code>uncaughtException</code> 丢失了当前环境的上下文，比如下面的例子就是它做不到的:</p>
<figure class="highlight javascript"><table><tr><td class="gutter"><pre><span class="line">1</span><br><span class="line">2</span><br><span class="line">3</span><br><span class="line">4</span><br><span class="line">5</span><br><span class="line">6</span><br><span class="line">7</span><br><span class="line">8</span><br><span class="line">9</span><br><span class="line">10</span><br></pre></td><td class="code"><pre><span class="line">app.get(<span class="string">'/'</span>, <span class="function"><span class="keyword">function</span> (<span class="params">req, res</span>) </span>&#123;</span><br><span class="line">    setTimeout(<span class="function"><span class="keyword">function</span> (<span class="params"></span>) </span>&#123;</span><br><span class="line">        <span class="keyword">throw</span> <span class="keyword">new</span> <span class="built_in">Error</span>(<span class="string">'async error'</span>); <span class="comment">// uncaughtException, 导致 req 的引用丢失</span></span><br><span class="line">        res.send(<span class="number">200</span>);</span><br><span class="line">    &#125;, <span class="number">1000</span>);</span><br><span class="line">&#125;);</span><br><span class="line"></span><br><span class="line">process.on(<span class="string">'uncaughtException'</span>, <span class="function"><span class="keyword">function</span> (<span class="params">err</span>) </span>&#123;</span><br><span class="line">    res.send(<span class="number">500</span>); <span class="comment">// 做不到，拿不到当前请求的 res 对象</span></span><br><span class="line">&#125;);</span><br></pre></td></tr></table></figure>

<p>最终出错的用户只能等待浏览器超时。</p>
<h2 id="domain-uncaughtException"><a href="#domain-uncaughtException" class="headerlink" title="domain + uncaughtException"></a><code>domain</code> + <code>uncaughtException</code></h2><p>所以，我们可以结合两种异常捕获机制，用 <code>domain</code> 来捕获大部分的异常，并且提供友好的 500 页面以及优雅退出。对于剩下的异常，通过 <code>uncaughtException</code> 事件来避免服务器直接 crash。</p>
<p>代码如下:</p>
<figure class="highlight javascript"><table><tr><td class="gutter"><pre><span class="line">1</span><br><span class="line">2</span><br><span class="line">3</span><br><span class="line">4</span><br><span class="line">5</span><br><span class="line">6</span><br><span class="line">7</span><br><span class="line">8</span><br><span class="line">9</span><br><span class="line">10</span><br><span class="line">11</span><br><span class="line">12</span><br><span class="line">13</span><br><span class="line">14</span><br><span class="line">15</span><br><span class="line">16</span><br><span class="line">17</span><br><span class="line">18</span><br><span class="line">19</span><br><span class="line">20</span><br><span class="line">21</span><br><span class="line">22</span><br><span class="line">23</span><br><span class="line">24</span><br><span class="line">25</span><br><span class="line">26</span><br><span class="line">27</span><br><span class="line">28</span><br><span class="line">29</span><br><span class="line">30</span><br><span class="line">31</span><br><span class="line">32</span><br><span class="line">33</span><br><span class="line">34</span><br><span class="line">35</span><br><span class="line">36</span><br><span class="line">37</span><br><span class="line">38</span><br><span class="line">39</span><br><span class="line">40</span><br></pre></td><td class="code"><pre><span class="line"><span class="keyword">var</span> app = express();</span><br><span class="line"><span class="keyword">var</span> server = <span class="built_in">require</span>(<span class="string">'http'</span>).create(app);</span><br><span class="line"><span class="keyword">var</span> domain = <span class="built_in">require</span>(<span class="string">'domain'</span>);</span><br><span class="line"></span><br><span class="line"><span class="comment">// 使用 domain 来捕获大部分异常</span></span><br><span class="line">app.use(<span class="function"><span class="keyword">function</span> (<span class="params">req, res, next</span>) </span>&#123;</span><br><span class="line">    <span class="keyword">var</span> reqDomain = domain.create();</span><br><span class="line">    reqDomain.on(<span class="string">'error'</span>, <span class="function"><span class="keyword">function</span> (<span class="params"></span>) </span>&#123;</span><br><span class="line">        <span class="keyword">try</span> &#123;</span><br><span class="line">            <span class="keyword">var</span> killTimer = setTimeout(<span class="function"><span class="keyword">function</span> (<span class="params"></span>) </span>&#123;</span><br><span class="line">                process.exit(<span class="number">1</span>);</span><br><span class="line">            &#125;, <span class="number">30000</span>);</span><br><span class="line">            killTimer.unref();</span><br><span class="line"></span><br><span class="line">            server.close();</span><br><span class="line"></span><br><span class="line">            res.send(<span class="number">500</span>);</span><br><span class="line">        &#125; <span class="keyword">catch</span> (e) &#123;</span><br><span class="line">            <span class="built_in">console</span>.log(<span class="string">'error when exit'</span>, e.stack);</span><br><span class="line">        &#125;</span><br><span class="line">    &#125;);</span><br><span class="line"></span><br><span class="line">    reqDomain.run(next);</span><br><span class="line">&#125;);</span><br><span class="line"></span><br><span class="line"><span class="comment">// uncaughtException 避免程序崩溃</span></span><br><span class="line">process.on(<span class="string">'uncaughtException'</span>, <span class="function"><span class="keyword">function</span> (<span class="params">err</span>) </span>&#123;</span><br><span class="line">    <span class="built_in">console</span>.log(err);</span><br><span class="line"></span><br><span class="line">    <span class="keyword">try</span> &#123;</span><br><span class="line">        <span class="keyword">var</span> killTimer = setTimeout(<span class="function"><span class="keyword">function</span> (<span class="params"></span>) </span>&#123;</span><br><span class="line">            process.exit(<span class="number">1</span>);</span><br><span class="line">        &#125;, <span class="number">30000</span>);</span><br><span class="line">        killTimer.unref();</span><br><span class="line"></span><br><span class="line">        server.close();</span><br><span class="line">    &#125; <span class="keyword">catch</span> (e) &#123;</span><br><span class="line">        <span class="built_in">console</span>.log(<span class="string">'error when exit'</span>, e.stack);</span><br><span class="line">    &#125;</span><br><span class="line">&#125;);</span><br></pre></td></tr></table></figure>

<h2 id="其他的一些问题"><a href="#其他的一些问题" class="headerlink" title="其他的一些问题"></a>其他的一些问题</h2><h3 id="express-中异常的处理"><a href="#express-中异常的处理" class="headerlink" title="express 中异常的处理"></a><code>express</code> 中异常的处理</h3><p>使用 <code>express</code> 时记住一定不要在 controller 的异步回调中抛出异常，例如:</p>
<figure class="highlight javascript"><table><tr><td class="gutter"><pre><span class="line">1</span><br><span class="line">2</span><br><span class="line">3</span><br><span class="line">4</span><br><span class="line">5</span><br><span class="line">6</span><br><span class="line">7</span><br><span class="line">8</span><br><span class="line">9</span><br><span class="line">10</span><br><span class="line">11</span><br><span class="line">12</span><br><span class="line">13</span><br></pre></td><td class="code"><pre><span class="line">app.get(<span class="string">'/'</span>, <span class="function"><span class="keyword">function</span> (<span class="params">req, res, next</span>) </span>&#123; <span class="comment">// 总是接收 next 参数</span></span><br><span class="line">    mysql.query(<span class="string">'SELECT * FROM users'</span>, <span class="function"><span class="keyword">function</span> (<span class="params">err, results</span>) </span>&#123;</span><br><span class="line">        <span class="comment">// 不要这样做</span></span><br><span class="line">        <span class="keyword">if</span> (err) <span class="keyword">throw</span> err;</span><br><span class="line"></span><br><span class="line">        <span class="comment">// 应该将 err 传递给 errorHandler 处理</span></span><br><span class="line">        <span class="keyword">if</span> (err) <span class="keyword">return</span> next(err);</span><br><span class="line">    &#125;);</span><br><span class="line">&#125;);</span><br><span class="line"></span><br><span class="line">app.use(<span class="function"><span class="keyword">function</span> (<span class="params">err, req, res, next</span>) </span>&#123; <span class="comment">// 带有四个参数的 middleware 专门用来处理异常</span></span><br><span class="line">    res.render(<span class="number">500</span>, err.stack);</span><br><span class="line">&#125;);</span><br></pre></td></tr></table></figure>

<h3 id="和-cluster-一起使用"><a href="#和-cluster-一起使用" class="headerlink" title="和 cluster 一起使用"></a>和 cluster 一起使用</h3><p>cluster 是 node 自带的负载均衡模块，使用 cluster 模块可以方便的建立起一套 master/slave 服务。在使用 cluster 模块时，需要注意不仅需要调用 <code>server.close()</code> 来关闭连接，同时还需要调用 <code>cluster.worker.disconnect()</code> 通知 master 进程已停止服务:</p>
<figure class="highlight javascript"><table><tr><td class="gutter"><pre><span class="line">1</span><br><span class="line">2</span><br><span class="line">3</span><br><span class="line">4</span><br><span class="line">5</span><br><span class="line">6</span><br><span class="line">7</span><br><span class="line">8</span><br><span class="line">9</span><br><span class="line">10</span><br><span class="line">11</span><br><span class="line">12</span><br><span class="line">13</span><br><span class="line">14</span><br><span class="line">15</span><br><span class="line">16</span><br><span class="line">17</span><br><span class="line">18</span><br><span class="line">19</span><br><span class="line">20</span><br></pre></td><td class="code"><pre><span class="line"><span class="keyword">var</span> cluster = <span class="built_in">require</span>(<span class="string">'cluster'</span>);</span><br><span class="line"></span><br><span class="line">process.on(<span class="string">'uncaughtException'</span>, <span class="function"><span class="keyword">function</span> (<span class="params">err</span>) </span>&#123;</span><br><span class="line">    <span class="built_in">console</span>.log(err);</span><br><span class="line"></span><br><span class="line">    <span class="keyword">try</span> &#123;</span><br><span class="line">        <span class="keyword">var</span> killTimer = setTimeout(<span class="function"><span class="keyword">function</span> (<span class="params"></span>) </span>&#123;</span><br><span class="line">            process.exit(<span class="number">1</span>);</span><br><span class="line">        &#125;, <span class="number">30000</span>);</span><br><span class="line">        killTimer.unref();</span><br><span class="line"></span><br><span class="line">        server.close();</span><br><span class="line"></span><br><span class="line">        <span class="keyword">if</span> (cluster.worker) &#123;</span><br><span class="line">            cluster.worker.disconnect();</span><br><span class="line">        &#125;</span><br><span class="line">    &#125; <span class="keyword">catch</span> (e) &#123;</span><br><span class="line">        <span class="built_in">console</span>.log(<span class="string">'error when exit'</span>, e.stack);</span><br><span class="line">    &#125;</span><br><span class="line">&#125;);</span><br></pre></td></tr></table></figure>

<h3 id="不要通过-uncaughtException-来忽略错误"><a href="#不要通过-uncaughtException-来忽略错误" class="headerlink" title="不要通过 uncaughtException 来忽略错误"></a>不要通过 <code>uncaughtException</code> 来忽略错误</h3><p>当 <code>uncaughtException</code> 事件有一个以上的 <code>listener</code> 时，会阻止 Node 结束进程。因此就有一个广泛流传的做法是监听 <code>process</code> 的 <code>uncaughtException</code> 事件来阻止进程退出，这种做法有内存泄露的风险，所以千万不要这么做:</p>
<figure class="highlight javascript"><table><tr><td class="gutter"><pre><span class="line">1</span><br><span class="line">2</span><br><span class="line">3</span><br></pre></td><td class="code"><pre><span class="line">process.on(<span class="string">'uncaughtException'</span>, <span class="function"><span class="keyword">function</span> (<span class="params">err</span>) </span>&#123; <span class="comment">// 不要这么做</span></span><br><span class="line">    <span class="built_in">console</span>.log(err);</span><br><span class="line">&#125;);</span><br></pre></td></tr></table></figure>
<h3 id="pm2-对于-uncaughtException-的额外处理"><a href="#pm2-对于-uncaughtException-的额外处理" class="headerlink" title="pm2 对于 uncaughtException 的额外处理"></a>pm2 对于 <code>uncaughtException</code> 的额外处理</h3><p>如果你在用 pm2 0.7.1 之前的版本，那么要当心。pm2 有一个 bug，如果进程抛出了 <code>uncaughtException</code>，无论代码中是否捕获了这个事件，进程都会被 pm2 杀死。0.7.2 之后的 pm2 解决了这个问题。</p>
<h3 id="要小心-worker-disconnect"><a href="#要小心-worker-disconnect" class="headerlink" title="要小心 worker.disconnect()"></a>要小心 worker.disconnect()</h3><p>如果你在退出进程时希望可以发消息给监控服务器，并且还使用了 cluster，那么这个时候要特别小心，比如下面的代码:</p>
<figure class="highlight javascript"><table><tr><td class="gutter"><pre><span class="line">1</span><br><span class="line">2</span><br><span class="line">3</span><br><span class="line">4</span><br><span class="line">5</span><br><span class="line">6</span><br><span class="line">7</span><br><span class="line">8</span><br><span class="line">9</span><br></pre></td><td class="code"><pre><span class="line"><span class="keyword">var</span> udpLog = dgram.createSocket(<span class="string">'udp4'</span>);</span><br><span class="line"><span class="keyword">var</span> cluster = <span class="built_in">require</span>(<span class="string">'cluster'</span>);</span><br><span class="line"></span><br><span class="line">process.on(<span class="string">'uncaughtException'</span>, <span class="function"><span class="keyword">function</span> (<span class="params">err</span>) </span>&#123;</span><br><span class="line">    udpLog.send(<span class="string">'process '</span> + process.pid + <span class="string">' down'</span>, <span class="comment">/* ... 一些发送 udp 消息的参数 ...*/</span>);</span><br><span class="line"></span><br><span class="line">    server.close();</span><br><span class="line">    cluster.worker.disconnect();</span><br><span class="line">&#125;);</span><br></pre></td></tr></table></figure>

<p>这份代码就不能正常的将消息发送出去。因为 <code>udpLog.send</code> 是一个异步方法，真正发消息的操作发生在下一个事件循环中。而在真正的发送消息之前 <code>cluster.worker.disconnect()</code> 就已经执行了。<code>worker.disconnect()</code> 会在当前进程没有任何链接之后，杀掉整个进程，这种情况有可能发生在发送 log 数据之前，导致 log 数据发不出去。</p>
<p>一个解决方法是在 <code>udpLog.send</code> 方法发送完数据后再调用 <code>worker.disconnect</code>:</p>
<figure class="highlight javascript"><table><tr><td class="gutter"><pre><span class="line">1</span><br><span class="line">2</span><br><span class="line">3</span><br><span class="line">4</span><br><span class="line">5</span><br><span class="line">6</span><br><span class="line">7</span><br><span class="line">8</span><br><span class="line">9</span><br><span class="line">10</span><br><span class="line">11</span><br><span class="line">12</span><br><span class="line">13</span><br><span class="line">14</span><br><span class="line">15</span><br></pre></td><td class="code"><pre><span class="line"><span class="keyword">var</span> udpLog = dgram.createSocket(<span class="string">'udp4'</span>);</span><br><span class="line"><span class="keyword">var</span> cluster = <span class="built_in">require</span>(<span class="string">'cluster'</span>);</span><br><span class="line"></span><br><span class="line">process.on(<span class="string">'uncaughtException'</span>, <span class="function"><span class="keyword">function</span> (<span class="params">err</span>) </span>&#123;</span><br><span class="line">    udpLog.send(<span class="string">'process '</span> + process.pid + <span class="string">' down'</span>, <span class="comment">/* ... 一些发送 udp 消息的参数 ...*/</span>, <span class="function"><span class="keyword">function</span> (<span class="params"></span>) </span>&#123;</span><br><span class="line">        cluster.worker.disconnect();</span><br><span class="line">    &#125;);</span><br><span class="line"></span><br><span class="line">    server.close();</span><br><span class="line"></span><br><span class="line">    <span class="comment">// 保证 worker.disconnect 不会拖太久..</span></span><br><span class="line">    setTimeout(<span class="function"><span class="keyword">function</span> (<span class="params"></span>) </span>&#123;</span><br><span class="line">        cluster.worker.disconnect();</span><br><span class="line">    &#125;, <span class="number">100</span>).unref();</span><br><span class="line">&#125;);</span><br></pre></td></tr></table></figure>

<h2 id="小节"><a href="#小节" class="headerlink" title="小节"></a>小节</h2><p>说了这么多，结论是，目前为止(Node 0.10.25)，依然没有一个完美的方案来解决任意异常的优雅退出问题。用 <code>domain</code> 来捕获大部分异常，并且通过 <code>uncaughtException</code> 避免程序 crash 是目前来说最理想的方案。回调异常的退出问题在遇到 cluster 以后会更加复杂，特别是对于连接关闭的处理要格外小心。</p>
<h2 id="参考文章"><a href="#参考文章" class="headerlink" title="参考文章"></a>参考文章</h2><ul>
<li><a href="http://nodejs.org/api/domain.html#domain_warning_don_t_ignore_errors" target="_blank" rel="noopener">Don’t ignore errors</a></li>
<li><a href="http://nodejs.org/api/domain.html" target="_blank" rel="noopener">Node API: domain</a></li>
<li><a href="http://nodejs.org/api/process.html" target="_blank" rel="noopener">Node API: process</a></li>
<li><a href="http://cnodejs.org/topic/516b64596d38277306407936" target="_blank" rel="noopener">Node.js 异步异常的处理与domain模块解析</a></li>
<li><a href="http://www.alloyteam.com/2013/12/node-js-series-exception-caught/" target="_blank" rel="noopener">Node.js异常捕获的一些实践</a></li>
</ul>
</div><div class="post-footer"><div class="meta"><div class="info"><i class="fa fa-sun-o"></i><span class="date">2014-01-25</span><i class="fa fa-tag"></i><a class="tag" href="/tags/node/" title="node">node </a></div></div></div></div><div class="pagination"><ul class="clearfix"><li class="pre pagbuttons"><a class="btn" role="navigation" href="/2014/02/26/docker-behind-gfw/" title="Mac 下使用代理连接 docker 镜像服务器">上一篇</a></li><li class="next pagbuttons"><a class="btn" role="navigation" href="/2013/10/16/use-nodejs-as-web-frontend-server/" title="用 node.js 做 Web 前端服务器的一些经验">下一篇</a></li></ul></div></div></div></div></div><script src="/js/jquery.js"></script><script src="/js/jquery-migrate-1.2.1.min.js"></script><script src="/js/jquery.appear.js"></script></body></html>